Workbook

Sheet All
A1: TCET
A2: Students Placement Register of 2025 Batch
A3: TCET/REG/IP-06/02 | J3: Revision: B
A4: REF: TCET/ T&P/ REP of 2026 | J4: 46127
A6: Sr.No. | B6: Branch Div | C6: T&P UID | D6: Student Name | E6: Date of Employer Visit | F6: Employer Category Super Dream / Dream/Normal | G6: Type of Placement | H6: Employer Name | I6: Stipend offered during PLI | J6: Salary offered for Placement ( INR-LPA.) | K6: No.of Offers | L6: Dual Offer | O6: Emil ID | P6: Mobile | Q6: Date of Joining | R6: Remark | S6: Phase
A7: 1 | B7: COMP-A | C7: 21-COMPA47-25 | D7: GUPTA JAGRITI ASHOK SEEMA | E7: 45345 | F7: Category-1 | G7: PLI | H7: VIC IT Consultancy | I7: 25000 | J7: 12 | K7: 2 | M7: =VLOOKUP(C7,'[1]As per ISO'!$B$7:$EQ$1026,146,0) -> #N/A | N7: =VLOOKUP(C7,'[2]As per ISO'!$B$7:$BV$1031,73,0) -> #N/A | O7: jagriti0815@gmail.com | P7: 8169947049 | S7: Phase-1 | T7: =IF(LEFT(H7,3)="off","OFF",IF(H7="","","ON")) -> ON | W7: =VLOOKUP(C7,#REF!,5,0) -> #REF!
A8: 2 | B8: CS&E | C8: 21-CS&E53-25 | D8: SINGH VAIBHAV RAKESH PRIYANKA | E8: 45345 | F8: Category-1 | G8: PLI | H8: VIC IT Consultancy | I8: 25000 | J8: 12 | M8: =VLOOKUP(C8,'[1]As per ISO'!$B$7:$EQ$1026,146,0) -> CAT-1 | N8: =VLOOKUP(C8,'[2]As per ISO'!$B$7:$BV$1031,73,0) -> ViCIT | O8: vaibhavsingh2633@gmail.com | P8: 9137957152 | S8: Phase-1 | T8: =IF(LEFT(H8,3)="off","OFF",IF(H8="","","ON")) -> ON | W8: =VLOOKUP(C8,#REF!,5,0) -> #REF!
A9: 3 | B9: IoT | C9: 21-IoT02-25 | D9: DHAWAN AYUSH VISHAL ANAMIKA | E9: 45422 | F9: Category-1 | G9: PLI | H9: J.P.Morgan & Chase | I9: 75000 | J9: 20 | K9: 2 | M9: =VLOOKUP(C9,'[1]As per ISO'!$B$7:$EQ$1026,146,0) -> CAT-1 | N9: =VLOOKUP(C9,'[2]As per ISO'!$B$7:$BV$1031,73,0) -> J.P Morgan &Chase | O9: dhawanayush416@gmail.com | P9: 8369342556 | S9: Phase-1 | T9: =IF(LEFT(H9,3)="off","OFF",IF(H9="","","ON")) -> ON | W9: =VLOOKUP(C9,#REF!,5,0) -> #REF!
A10: 4 | B10: COMP-C | C10: 21-COMPC20-25 | D10: SINGH DHIRENDRA SHERBAHADUR MEENA | E10: 45422 | F10: Category-1 | G10: PLI | H10: J.P.Morgan & Chase | I10: 75000 | J10: 20 | M10: =VLOOKUP(C10,'[1]As per ISO'!$B$7:$EQ$1026,146,0) -> CAT-1 | N10: =VLOOKUP(C10,'[2]As per ISO'!$B$7:$BV$1031,73,0) -> J.P Morgan &Chase | O10: dhirendrasingh.professional@gmail.com | P10: 8698867967 | S10: Phase-1 | T10: =IF(LEFT(H10,3)="off","OFF",IF(H10="","","ON")) -> ON | W10: =VLOOKUP(C10,#REF!,5,0) -> #REF!
A11: 5 | B11: AI&DS | C11: 21-AI&DS25-25 | D11: PANDEY ANANTA SHRIKANT KARUNA | E11: 45504 | F11: Category-3 | G11: PLI | H11: Blackcurrant Apps | I11: 5000 | J11: 4 | K11: 6 | M11: =VLOOKUP(C11,'[1]As per ISO'!$B$7:$EQ$1026,146,0) -> CAT-1 | N11: =VLOOKUP(C11,'[2]As per ISO'!$B$7:$BV$1031,73,0) -> Blackcurrrant Apps | O11: anantask.e04@gmail.com | P11: 7977611489 | S11: Phase-1 | T11: =IF(LEFT(H11,3)="off","OFF",IF(H11="","","ON")) -> ON | W11: =VLOOKUP(C11,#REF!,5,0) -> #REF!
A12: 6 | B12: AI&ML | C12: 22-AI&ML66-25 | D12: SHAIKH DANISH MASOOD KHALID SABERA | E12: 45504 | F12: Category-3 | G12: PLI | H12: Blackcurrant Apps | I12: 5000 | J12: 4 | M12: =VLOOKUP(C12,'[1]As per ISO'!$B$7:$EQ$1026,146,0) -> CAT-1 | N12: =VLOOKUP(C12,'[2]As per ISO'!$B$7:$BV$1031,73,0) -> Blackcurrrant Apps | O12: danishmasoodshk3@gmail.com | P12: 7045543311 | S12: Phase-1 | T12: =IF(LEFT(H12,3)="off","OFF",IF(H12="","","ON")) -> ON | W12: =VLOOKUP(C12,#REF!,5,0) -> #REF!
A13: 7 | B13: CS&E | C13: 21-CS&E10-25 | D13: DUBEY PRAHARSH SHAILESH ARCHANA | E13: 45504 | F13: Category-2 | G13: PLI | H13: Blackcurrrant Apps | I13: 5000 | J13: 5 | M13: =VLOOKUP(C13,'[1]As per ISO'!$B$7:$EQ$1026,146,0) -> CAT-1 | N13: =VLOOKUP(C13,'[2]As per ISO'!$B$7:$BV$1031,73,0) -> Blackcurrrant Apps | O13: praharshdubey2003@gmail.com | P13: 9930683671 | S13: Phase-1 | T13: =IF(LEFT(H13,3)="off","OFF",IF(H13="","","ON")) -> ON | W13: =VLOOKUP(C13,#REF!,5,0) -> #REF!
A14: 8 | B14: IT-A | C14: 21-ITA31-25 | D14: GUPTA ARVIND LALMAN VIDHYAWATI | E14: 45504 | F14: Category-2 | G14: PLI | H14: Blackcurrrant Apps | I14: 5000 | J14: 5.5 | M14: =VLOOKUP(C14,'[1]As per ISO'!$B$7:$EQ$1026,146,0) -> CAT-1 | N14: =VLOOKUP(C14,'[2]As per ISO'!$B$7:$BV$1031,73,0) -> Blackcurrrant Apps | O14: guptaarvind2602@gmail.com | P14: 9833911446 | S14: Phase-1 | T14: =IF(LEFT(H14,3)="off","OFF",IF(H14="","","ON")) -> ON | W14: =VLOOKUP(C14,#REF!,5,0) -> #REF!
A15: 9 | B15: IT-B | C15: 21-ITB52-25 | D15: THOMBRE AAROHI VIJAY SHILPA | E15: 45504 | F15: Category-2 | G15: PLI | H15: Blackcurrrant Apps | I15: 5000 | J15: 5 | M15: =VLOOKUP(C15,'[1]As per ISO'!$B$7:$EQ$1026,146,0) -> CAT-1 | N15: =VLOOKUP(C15,'[2]As per ISO'!$B$7:$BV$1031,73,0) -> Blackcurrrant Apps | O15: thombreaarohi.work555@gmail.com | P15: 9136137965 | S15: Phase-1 | T15: =IF(LEFT(H15,3)="off","OFF",IF(H15="","","ON")) -> ON | W15: =VLOOKUP(C15,#REF!,5,0) -> #REF!
A16: 10 | B16: IT-B | C16: 21-ITB59-25 | D16: VISHWAKARMA JAY RAJESH ANITA | E16: 45504 | F16: Category-2 | G16: PLI | H16: Blackcurrrant Apps | I16: 5000 | J16: 5 | M16: =VLOOKUP(C16,'[1]As per ISO'!$B$7:$EQ$1026,146,0) -> CAT-1 | N16: =VLOOKUP(C16,'[2]As per ISO'!$B$7:$BV$1031,73,0) -> Blackcurrrant Apps | O16: vishwakarmajay292@gmail.com | P16: 9372454445 | S16: Phase-1 | T16: =IF(LEFT(H16,3)="off","OFF",IF(H16="","","ON")) -> ON | W16: =VLOOKUP(C16,#REF!,5,0) -> #REF!
A17: 11 | B17: IT-A | C17: 22-ITA67-25 | D17: CHAURASIYA SHIVANGI CHATURBHUJ | E17: 45511 | F17: Category-2 | G17: PLI | H17: Saint Gobain | I17: 20000 | J17: 6.5 | K17: 3 | M17: =VLOOKUP(C17,'[1]As per ISO'!$B$7:$EQ$1026,146,0) -> CAT-1 | N17: =VLOOKUP(C17,'[2]As per ISO'!$B$7:$BV$1031,73,0) -> Saint Gobain | O17: chaurasiyashivangi7@gmail.com | P17: 9326259449 | S17: Phase-1 | T17: =IF(LEFT(H17,3)="off","OFF",IF(H17="","","ON")) -> ON | W17: =VLOOKUP(C17,#REF!,5,0) -> #REF!
A18: 12 | B18: IT-B | C18: 21-ITB60-25 | D18: VYAS AISHWARYA DINESH RUPA | E18: 45511 | F18: Category-2 | G18: PLI | H18: Saint Gobain | I18: 20000 | J18: 6.5 | M18: =VLOOKUP(C18,'[1]As per ISO'!$B$7:$EQ$1026,146,0) -> CAT-1 | N18: =VLOOKUP(C18,'[2]As per ISO'!$B$7:$BV$1031,73,0) -> Saint Gobain | O18: aishwaryavyas0703@gmail.com | P18: 9619501546 | S18: Phase-1 | T18: =IF(LEFT(H18,3)="off","OFF",IF(H18="","","ON")) -> ON | W18: =VLOOKUP(C18,#REF!,5,0) -> #REF!
A19: 13 | B19: IT-B | C19: 22-ITB68-25 | D19: RAI AASTHA SARVESH SULAKSHANA | E19: 45511 | F19: Category-2 | G19: PLI | H19: Saint Gobain | I19: 20000 | J19: 6.5 | M19: =VLOOKUP(C19,'[1]As per ISO'!$B$7:$EQ$1026,146,0) -> CAT-1 | N19: =VLOOKUP(C19,'[2]As per ISO'!$B$7:$BV$1031,73,0) -> Saint Gobain | O19: aasthasrai@gmail.com | P19: 9967063058 | S19: Phase-1 | T19: =IF(LEFT(H19,3)="off","OFF",IF(H19="","","ON")) -> ON | W19: =VLOOKUP(C19,#REF!,5,0) -> #REF!
A20: 14 | B20: AI&ML | C20: 21-AI&ML58-25 | D20: YADAV KRISHNAKUMAR RADHIKAPRASAD RAMAVATI | E20: 45513 | F20: Category-2 | G20: Regular | H20: Oracle Financial Services Software Limited | J20: 9.34 | K20: 13 | M20: =VLOOKUP(C20,'[1]As per ISO'!$B$7:$EQ$1026,146,0) -> CAT-1 | N20: =VLOOKUP(C20,'[2]As per ISO'!$B$7:$BV$1031,73,0) -> Oracle | O20: krishna251203@gmail.com | P20: 7738240155 | S20: Phase-1 | T20: =IF(LEFT(H20,3)="off","OFF",IF(H20="","","ON")) -> ON
A21: 15 | B21: COMP-B | C21: 21-COMPB18-25 | D21: MISHRA SHASHANK JITENDRA JAYSHREE | E21: 45513 | F21: Category-2 | G21: Regular | H21: Oracle Financial Services Software Limited | J21: 9.34 | M21: =VLOOKUP(C21,'[1]As per ISO'!$B$7:$EQ$1026,146,0) -> CAT-1 | N21: =VLOOKUP(C21,'[2]As per ISO'!$B$7:$BV$1031,73,0) -> Oracle | O21: shashankbud80@gmail.com | P21: 7887541843 | S21: Phase-1 | T21: =IF(LEFT(H21,3)="off","OFF",IF(H21="","","ON")) -> ON
A22: 16 | B22: COMP-B | C22: 21-COMPB44-25 | D22: PRAJAPATI SHLOK DEVENDRA SARITA | E22: 45513 | F22: Category-2 | G22: Regular | H22: Oracle Financial Services Software Limited | J22: 9.34 | M22: =VLOOKUP(C22,'[1]As per ISO'!$B$7:$EQ$1026,146,0) -> CAT-1 | N22: =VLOOKUP(C22,'[2]As per ISO'!$B$7:$BV$1031,73,0) -> Oracle | O22: shlokprajapati2003@gmail.com | P22: 7977960433 | S22: Phase-1 | T22: =IF(LEFT(H22,3)="off","OFF",IF(H22="","","ON")) -> ON
A23: 17 | B23: COMP-C | C23: 21-COMPC19-25 | D23: SINGH AYUSH MAHESHKUMAR RINKY | E23: 45513 | F23: Category-2 | G23: Regular | H23: Oracle Financial Services Software Limited | J23: 9.34 | M23: =VLOOKUP(C23,'[1]As per ISO'!$B$7:$EQ$1026,146,0) -> CAT-1 | N23: =VLOOKUP(C23,'[2]As per ISO'!$B$7:$BV$1031,73,0) -> Oracle | O23: ayushsingh00030@gmail.com | P23: 9321802886 | S23: Phase-1 | T23: =IF(LEFT(H23,3)="off","OFF",IF(H23="","","ON")) -> ON
A24: 18 | B24: COMP-C | C24: 21-COMPC23-25 | D24: SINGH PARTH PARSHURAM SUMAN | E24: 45513 | F24: Category-2 | G24: Regular | H24: Oracle Financial Services Software Limited | J24: 9.34 | M24: =VLOOKUP(C24,'[1]As per ISO'!$B$7:$EQ$1026,146,0) -> CAT-1 | N24: =VLOOKUP(C24,'[2]As per ISO'!$B$7:$BV$1031,73,0) -> Oracle | O24: parth3743@gmail.com | P24: 8263939916 | S24: Phase-1 | T24: =IF(LEFT(H24,3)="off","OFF",IF(H24="","","ON")) -> ON
A25: 19 | B25: COMP-C | C25: 21-COMPC44-25 | D25: VARMA BHARGAV ASHOKKUMAR SONI | E25: 45513 | F25: Category-2 | G25: Regular | H25: Oracle Financial Services Software Limited | J25: 9.34 | M25: =VLOOKUP(C25,'[1]As per ISO'!$B$7:$EQ$1026,146,0) -> CAT-1 | N25: =VLOOKUP(C25,'[2]As per ISO'!$B$7:$BV$1031,73,0) -> Oracle | O25: bhargavva46@gmail.com | P25: 9324085589 | S25: Phase-1 | T25: =IF(LEFT(H25,3)="off","OFF",IF(H25="","","ON")) -> ON
A26: 20 | B26: COMP-C | C26: 21-COMPC45-25 | D26: VAVDANE PRASAD SURYABHAN NUTAN | E26: 45513 | F26: Category-2 | G26: Regular | H26: Oracle Financial Services Software Limited | J26: 9.34 | M26: =VLOOKUP(C26,'[1]As per ISO'!$B$7:$EQ$1026,146,0) -> CAT-1 | N26: =VLOOKUP(C26,'[2]As per ISO'!$B$7:$BV$1031,73,0) -> Oracle | O26: prasadvavdane45@gmail.com | P26: 8976338037 | S26: Phase-1 | T26: =IF(LEFT(H26,3)="off","OFF",IF(H26="","","ON")) -> ON
A27: 21 | B27: COMP-C | C27: 21-COMPC50-25 | D27: VISHWAKARMA SANSKAR RAKESH MAMTA | E27: 45513 | F27: Category-2 | G27: Regular | H27: Oracle Financial Services Software Limited | J27: 9.34 | M27: =VLOOKUP(C27,'[1]As per ISO'!$B$7:$EQ$1026,146,0) -> CAT-1 | N27: =VLOOKUP(C27,'[2]As per ISO'!$B$7:$BV$1031,73,0) -> Oracle | O27: sanskarv2004@gmail.com | P27: 9321597049 | S27: Phase-1 | T27: =IF(LEFT(H27,3)="off","OFF",IF(H27="","","ON")) -> ON
A28: 22 | B28: COMP-C | C28: 21-COMPC57-25 | D28: YADAV SAHIL JAGATPAL SUSHMA | E28: 45513 | F28: Category-2 | G28: Regular | H28: Oracle Financial Services Software Limited | J28: 9.34 | M28: =VLOOKUP(C28,'[1]As per ISO'!$B$7:$EQ$1026,146,0) -> CAT-1 | N28: =VLOOKUP(C28,'[2]As per ISO'!$B$7:$BV$1031,73,0) -> Oracle | O28: sahil.jp.yadav@gmail.com | P28: 9324029051 | S28: Phase-1 | T28: =IF(LEFT(H28,3)="off","OFF",IF(H28="","","ON")) -> ON
A29: 23 | B29: CS&E | C29: 21-CS&E18-25 | D29: SINGH VIVEK DILIP MERI | E29: 45513 | F29: Category-2 | G29: Regular | H29: Oracle Financial Services Software Limited | J29: 9.34 | M29: =VLOOKUP(C29,'[1]As per ISO'!$B$7:$EQ$1026,146,0) -> CAT-1 | N29: =VLOOKUP(C29,'[2]As per ISO'!$B$7:$BV$1031,73,0) -> Oracle | O29: viveksngh2611@gmail.com | P29: 9324498412 | S29: Phase-1 | T29: =IF(LEFT(H29,3)="off","OFF",IF(H29="","","ON")) -> ON
A30: 24 | B30: IT-A | C30: 22-ITA66-25 | D30: AMIN TANISHA VASANTHA NAGAVENI | E30: 45513 | F30: Category-2 | G30: Regular | H30: Oracle Financial Services Software Limited | J30: 9.34 | M30: =VLOOKUP(C30,'[1]As per ISO'!$B$7:$EQ$1026,146,0) -> CAT-1 | N30: =VLOOKUP(C30,'[2]As per ISO'!$B$7:$BV$1031,73,0) -> Oracle | O30: amintanisha29@gmail.com | P30: 7264070717 | S30: Phase-1 | T30: =IF(LEFT(H30,3)="off","OFF",IF(H30="","","ON")) -> ON
A31: 25 | B31: IT-B | C31: 21-ITB04-25 | D31: PANDEY ANAND AWADHESH SUSHEELA | E31: 45513 | F31: Category-2 | G31: Regular | H31: Oracle Financial Services Software Limited | J31: 9.34 | M31: =VLOOKUP(C31,'[1]As per ISO'!$B$7:$EQ$1026,146,0) -> CAT-1 | N31: =VLOOKUP(C31,'[2]As per ISO'!$B$7:$BV$1031,73,0) -> Oracle | O31: anandpandey0205@gmail.com | P31: 9082668373 | S31: Phase-1 | T31: =IF(LEFT(H31,3)="off","OFF",IF(H31="","","ON")) -> ON
A32: 26 | B32: IT-B | C32: 21-ITB62-25 | D32: YADAV NANDINI MAHENDRA NIRMALA | E32: 45513 | F32: Category-2 | G32: Regular | H32: Oracle Financial Services Software Limited | J32: 9.34 | M32: =VLOOKUP(C32,'[1]As per ISO'!$B$7:$EQ$1026,146,0) -> CAT-1 | N32: =VLOOKUP(C32,'[2]As per ISO'!$B$7:$BV$1031,73,0) -> Oracle | O32: nandiniy044@gmail.com | P32: 9172859753 | S32: Phase-1 | T32: =IF(LEFT(H32,3)="off","OFF",IF(H32="","","ON")) -> ON
A33: 27 | B33: AI&ML | C33: 21-AI&ML17-25 | D33: KADRI ADIYAN SALEEM DILNAWAZ | E33: 45520 | F33: Category-2 | G33: Regular | H33: Infosys-Specialist Programmer(HWI) | J33: 9.5 | K33: 4 | M33: =VLOOKUP(C33,'[1]As per ISO'!$B$7:$EQ$1026,146,0) -> CAT-3 | N33: =VLOOKUP(C33,'[2]As per ISO'!$B$7:$BV$1031,73,0) -> Infosys-HWI-Specialist Programe | O33: kadriadiyan6@gmail.com | P33: 7977381198 | Q33: 45897 | S33: Phase-1 | T33: =IF(LEFT(H33,3)="off","OFF",IF(H33="","","ON")) -> ON
A34: 28 | B34: COMP-A | C34: 21-COMPA37-25 | D34: GAUR ANURAG MANOJKUMAR POONAM | E34: 45520 | F34: Category-2 | G34: PLI | H34: Infosys-Specialist Programmer | I34: 25000 | J34: 9.5 | M34: =VLOOKUP(C34,'[1]As per ISO'!$B$7:$EQ$1026,146,0) -> CAT-1 | N34: =VLOOKUP(C34,'[2]As per ISO'!$B$7:$BV$1031,73,0) -> Infosys-HWI-Specialist Programe | O34: anuragaur01@gmail.com | P34: 9819399208 | Q34: 45658 | R34: Already joined | S34: Phase-1 | T34: =IF(LEFT(H34,3)="off","OFF",IF(H34="","","ON")) -> ON | W34: =VLOOKUP(C34,#REF!,5,0) -> #REF!
A35: 29 | B35: IT-A | C35: 21-ITA26-25 | D35: GAUR ADITYA RAJESHKUMAR GAUR ROSHNI | E35: 45520 | F35: Category-2 | G35: Regular | H35: Infosys-Specialist Programmer | J35: 9.5 | M35: =VLOOKUP(C35,'[1]As per ISO'!$B$7:$EQ$1026,146,0) -> CAT-1 | O35: gauraditya63@gmail.com | P35: 7718043905 | Q35: 45897 | S35: Phase-1 | T35: =IF(LEFT(H35,3)="off","OFF",IF(H35="","","ON")) -> ON
A36: 30 | B36: IT-B | C36: 21-ITB42-25 | D36: SINGH NEHA AJAY KUMAR SUMAN | E36: 45520 | F36: Category-2 | G36: PLI | H36: Infosys-Specialist Programmer(HWI) | I36: 25000 | J36: 9.5 | M36: =VLOOKUP(C36,'[1]As per ISO'!$B$7:$EQ$1026,146,0) -> CAT-1 | O36: singhneha7182@gmail.com | P36: 8766638225 | Q36: 45658 | R36: Already joined | S36: Phase-1 | T36: =IF(LEFT(H36,3)="off","OFF",IF(H36="","","ON")) -> ON | W36: =VLOOKUP(C36,#REF!,5,0) -> #REF!
A37: 31 | B37: COMP-A | C37: 21-COMPA38-25 | D37: GHARAT DHRUV RAJKUMAR MINAL | E37: 45518 | F37: Category-3 | G37: Regular | H37: Vistaar | J37: 4 | K37: 1 | L37: 1 | M37: =VLOOKUP(C37,'[1]As per ISO'!$B$7:$EQ$1026,146,0) -> CAT-1 | N37: =VLOOKUP(C37,'[2]As per ISO'!$B$7:$BV$1031,73,0) -> Vistaar Systems Pvt.Ltd. | O37: dhruvrg2003@gmail.com | P37: 7709468189 | S37: Phase-1 | T37: =IF(LEFT(H37,3)="off","OFF",IF(H37="","","ON")) -> ON
A38: 32 | B38: COMP-A | C38: 21-COMPA40-25 | D38: GHORA KAMALIKA PRASANTA SUSMITA | E38: 45528 | F38: Category-1 | G38: PLI | H38: Flipkart | I38: 40000 | J38: 10.7 | K38: 5 | M38: =VLOOKUP(C38,'[1]As per ISO'!$B$7:$EQ$1026,146,0) -> CAT-1 | N38: 45670 | O38: kamalikaghora14@gmail.com | P38: 8459803092 | S38: Phase-1 | T38: =IF(LEFT(H38,3)="off","OFF",IF(H38="","","ON")) -> ON | W38: =VLOOKUP(C38,#REF!,5,0) -> #REF!
A39: 33 | B39: COMP-B | C39: 21-COMPB26-25 | D39: MOURYA SUJITKUMAR RADHESHYAM CHANDRAVATI | E39: 45528 | F39: Category-1 | G39: PLI | H39: Flipkart | I39: 40000 | J39: 10.7 | M39: =VLOOKUP(C39,'[1]As per ISO'!$B$7:$EQ$1026,146,0) -> CAT-1 | N39: 45670 | O39: mouryasujit04@gmail.com | P39: 9920224575 | S39: Phase-1 | T39: =IF(LEFT(H39,3)="off","OFF",IF(H39="","","ON")) -> ON | W39: =VLOOKUP(C39,#REF!,5,0) -> #REF!
A40: 34 | B40: CS&E | C40: 21-CS&E61-25 | D40: WALUNJ VAIBHAV DASHRATH SHOBHA | E40: 45528 | F40: Category-1 | G40: PLI | H40: Flipkart | I40: 40000 | J40: 10.7 | M40: =VLOOKUP(C40,'[1]As per ISO'!$B$7:$EQ$1026,146,0) -> CAT-1 | N40: 45670 | O40: vaibhavwalunj03@gmail.com | P40: 9022121405 | S40: Phase-1 | T40: =IF(LEFT(H40,3)="off","OFF",IF(H40="","","ON")) -> ON | W40: =VLOOKUP(C40,#REF!,5,0) -> #REF!
A41: 35 | B41: IT-B | C41: 21-ITB11-25 | D41: PATEL SEJAL DEVENDRA VINITA | E41: 45528 | F41: Category-1 | G41: PLI | H41: Flipkart | I41: 40000 | J41: 10.7 | M41: =VLOOKUP(C41,'[1]As per ISO'!$B$7:$EQ$1026,146,0) -> CAT-1 | N41: 45670 | O41: sp370135@gmail.com | P41: 8799895163 | S41: Phase-1 | T41: =IF(LEFT(H41,3)="off","OFF",IF(H41="","","ON")) -> ON | W41: =VLOOKUP(C41,#REF!,5,0) -> #REF!
...

Sheet Normal Average
B3: AI&DS | C3: AI&ML | D3: IOT | E3: COMP | F3: CS&E | G3: E&CS | H3: E&TC | I3: IT | J3: MECH | K3: MME | L3: CIVIL | M3: Total
B4: 9 | C4: 9.5 | D4: 40 | E4: 20 | F4: 12 | G4: 7 | H4: 10 | I4: 19.5 | J4: 5.6 | K4: 6.5 | L4: 5 | M4: 40
B5: 8.29 | C5: 9.34 | D5: 20 | E5: 19.5 | F5: 11.29 | G5: 6.5 | H5: 8.65 | I5: 10.7 | J5: 5 | K5: 6.5 | L5: 4 | M5: 20
B6: 7.75 | C6: 7.75 | D6: 6 | E6: 12 | F6: 10.7 | G6: 6 | H6: 8.5 | I6: 9.5 | J6: 4.25 | K6: 5.6 | L6: 3.75 | M6: 19.5
B7: 7 | C7: 7 | D7: 4.8 | E7: 10.7 | F7: 9.34 | G7: 5.75 | H7: 8.29 | I7: 9.34 | J7: 4.2 | K7: 5.5 | L7: 3.6 | M7: 12
B8: 6 | C8: 6 | D8: 4.5 | E8: 9.5 | F8: 8.29 | G8: 5.2 | H8: 7.5 | I8: 9 | J8: 4 | K8: 5 | L8: 3.5 | M8: 11.29
B9: 5.75 | C9: 5 | D9: 4.32 | E9: 9.34 | F9: 8 | G9: 5 | H9: 6 | I9: 8.29 | J9: 3.75 | K9: 5 | M9: 10.7
B10: 5 | C10: 5 | D10: 4.25 | E10: 9 | F10: 7.75 | G10: 4.25 | H10: 5.75 | I10: 8 | J10: 3.7 | K10: 4.8 | M10: 10
B11: 4.5 | C11: 4.5 | D11: 4 | E11: 8.5 | F11: 7.08 | G11: 4.2 | H11: 5.25 | I11: 7.05 | J11: 3.6 | K11: 4.5 | M11: 9.5
B12: 4.25 | C12: 4.25 | D12: 3.6 | E12: 8.29 | F12: 6.5 | G12: 4 | H12: 5 | I12: 7 | J12: 3.5 | K12: 4.2 | M12: 9.34
B13: 4.23 | C13: 4.2 | D13: 3.5 | E13: 8 | F13: 6 | G13: 3.6 | H13: 4.9 | I13: 6.5 | K13: 4 | M13: 9
B14: 4.2 | C14: 4 | D14: 3.5 | E14: 7.75 | F14: 5.75 | G14: 3.5 | H14: 4.5 | I14: 6.23 | K14: 3.8 | M14: 8.65
B15: 4 | C15: 4 | E15: 7.5 | F15: 5.5 | H15: 4.25 | I15: 6 | K15: 3.68 | M15: 8.5
B16: 3.6 | C16: 3.6 | E16: 7.35 | F16: 5 | H16: 4 | I16: 5.75 | K16: 3.6 | M16: 8.29
B17: 3.5 | C17: 3.5 | E17: 7 | F17: 5 | H17: 3.6 | I17: 5.5 | K17: 3.6 | M17: 8
E18: 6.5 | F18: 4.8 | H18: 3.5 | I18: 5 | K18: 3.6 | M18: 7.75
E19: 6.23 | F19: 4.5 | I19: 4.8 | K19: 3.5 | M19: 7.5
E20: 6.13 | F20: 4.5 | I20: 4.5 | K20: 3.5 | M20: 7.35
E21: 6 | F21: 4.25 | I21: 4.25 | M21: 7.08
E22: 5.75 | F22: 4 | I22: 4.2 | M22: 7.05
E23: 5.5 | F23: 3.6 | I23: 4 | M23: 7
E24: 5.2 | F24: 3.5 | I24: 3.6 | M24: 6.5
E25: 5 | F25: 3.5 | I25: 3.5 | M25: 6.23
E26: 4.8 | M26: 6.13
E27: 4.55 | M27: 6
E28: 4.5 | M28: 5.75
E29: 4.5 | M29: 5.6
E30: 4.45 | M30: 5.5
E31: 4.25 | M31: 5.25
E32: 4 | M32: 5.2
E33: 4 | M33: 5
E34: 3.6 | M34: 4.9
E35: 3.5 | M35: 4.8
M36: 4.55
M37: 4.5
M38: 4.45
M39: 4.32
M40: 4.25
M41: 4.23
M42: 4.2
...

Sheet Sheet1
D1: 40
D2: 20
D3: 19.5
D4: 12
D5: 11.29
D6: 10.7
D7: 10
D8: 9.5
D9: 9.34
D10: 9
D11: 8.65
D12: 8.5
... D51: 1.2

Sheet new (2)
A1: TCET
A2: Students Placement Register of 2021 Batch
A3: TCET/REG/IP-06/02
F4: 44210
A5: SR. NO. | B5: DATE OF VISIT | C5: NAME OF THE COMPANY | D5: NUMBER OF Offer's | E5: No. OF STUDENTS PLACED | F5: NAME OF THE STUDENTS PLACED | G5: Salary offered ( INR-LPA.) | H5: BRANCH | I5: UID
A6: 1 | B6: 44073 | C6: Capgemini | D6: 69 | E6: 1 | F6: AGARWAL AYUSH ASHOK RANJANA (Already placed in Oracle) | G6: 3.8 | H6: COMP-A | I6: 17-COMPA03-21
C7: Capgemini | E7: 2 | F7: AGRAWAL LOKESH VINODKUMAR ARCHANA | G7: 3.8 | H7: COMP-A | I7: 17-COMPA05-21
C8: Capgemini | E8: 3 | F8: CHAUDHARI PUSHPAK NANDKISHOR YOGITA | G8: 3.8 | H8: COMP-A | I8: 17-COMPA16-21
C9: Capgemini | E9: 4 | F9: DAHIMA PAARTH VIJAYKMUAR SINGH | G9: 3.8 | H9: COMP-A | I9: 17-COMPA20-21
C10: Capgemini | E10: 5 | F10: DEODHAR MITESH MEGHSHYAM MINAL | G10: 3.8 | H10: COMP-A | I10: 17-COMPA22-21
C11: Capgemini | E11: 6 | F11: GAUR GUNJAN SHIVBHAGWAN CHANDRKALA | G11: 3.8 | H11: COMP-A | I11: 17-COMPA30-21
C12: Capgemini | E12: 7 | F12: GUNDECHA BHAVIN SHANTILAL SHARMILA | G12: 3.8 | H12: COMP-A | I12: 17-COMPA35-21
C13: Capgemini | E13: 8 | F13: INANI JEET KUNTIPRAKASH MANJU (Already placed in Oracle) | G13: 3.8 | H13: COMP-A | I13: 17-COMPA39-21
C14: Capgemini | E14: 9 | F14: JAIN ADITYA VINAYKUMAR KALPANA | G14: 3.8 | H14: COMP-A | I14: 17-COMPA40-21
C15: Capgemini | E15: 10 | F15: KABRA VANSHIKA SATISH SARITA | G15: 3.8 | H15: COMP-A | I15: 17-COMPA47-21
C16: Capgemini | E16: 11 | F16: KHACHANE SHREYAS VIDYASHARAN KHACHANE KUMUDINI KHACHANE | G16: 3.8 | H16: COMP-A | I16: 17-COMPA51-21
C17: Capgemini | E17: 12 | F17: MISHRA SACHIN RAVINDRAKUMAR PREMLATA | G17: 3.8 | H17: COMP-A | I17: 17-COMPA63-21
C18: Capgemini | E18: 13 | F18: NAG ADITYA DINESH BINDU | G18: 3.8 | H18: COMP-B | I18: 17-COMPB06-21 | M18: =127-15 -> 112
C19: Capgemini | E19: 14 | F19: PANDEY ANSHIKA KRISHNADEV SUBHAVATI (Already placed in Infosys) | G19: 3.8 | H19: COMP-B | I19: 17-COMPB10-21
C20: Capgemini | E20: 15 | F20: PAWAR SASHANK SUBHASH CHANCHAL (Already placed in Infosys) | G20: 3.8 | H20: COMP-B | I20: 17-COMPB19-21
C21: Capgemini | E21: 16 | F21: SHAH AESHA SANDEEP BEENA | G21: 3.8 | H21: COMP-B | I21: 17-COMPB27-21
C22: Capgemini | E22: 17 | F22: SHAH DHRUVAL MANOJ URJITA | G22: 3.8 | H22: COMP-B | I22: 17-COMPB28-21
C23: Capgemini | E23: 18 | F23: SHARMA PRITHVI GHANSHYAM RANJEETA | G23: 3.8 | H23: COMP-B | I23: 17-COMPB31-21
C24: Capgemini | E24: 19 | F24: SINGH SAKSHI MUNNA SADHANA | G24: 3.8 | H24: COMP-B | I24: 17-COMPB44-21
C25: Capgemini | E25: 20 | F25: SINGH SRISHTI JITENDRA POONAM | G25: 3.8 | H25: COMP-B | I25: 17-COMPB46-21
C26: Capgemini | E26: 21 | F26: SINGH VAIBHAV RAMSURATPRASAD LALPARI | G26: 3.8 | H26: COMP-B | I26: 17-COMPB48-21
C27: Capgemini | E27: 22 | F27: SINGHVI RITAM AMRUT BHARTI | G27: 3.8 | H27: COMP-B | I27: 17-COMPB51-21
C28: Capgemini | E28: 23 | F28: UPADHYAY PRASHANT JOGENDRA SONI (Already placed in Infosys) | G28: 3.8 | H28: COMP-B | I28: 17-COMPB57-21
C29: Capgemini | E29: 24 | F29: YADAV ABHISHEK RAMESH CHINTA | G29: 3.8 | H29: COMP-B | I29: 17-COMPB60-21
C30: Capgemini | E30: 25 | F30: BHOGATE RUCHI BHALCHANDRA SHILPA | G30: 3.8 | H30: ELEX | I30: 17-ETRX04-21
... C59: Capgemini | E59: 54 | F59: PRADHAN TANVI SACHIN VAISHALI | G59: 3.8 | H59: IT-B | I59: 17-ITB17-21
C60: Capgemini | E60: 55 | F60: RANAWAT PARTH DINESH NEELAM ( Alredy plcaed in L&T Infotech) | G60: 3.8 | H60: IT-B | I60: #N/A
C61: Capgemini | E61: 56 | F61: SHAH DHAIRYA CHETAN JIGNA (Already placed in Oracle) | G61: 3.8 | H61: IT-B | I61: #N/A
C62: Capgemini | E62: 57 | F62: SHAH MILONI KIRIT VAISHALI | G62: 3.8 | H62: IT-B | I62: 17-ITB28-21
C63: Capgemini | E63: 58 | F63: SINGH ANUSHKA UMASHANKAR BHAGYALAXMI | G63: 3.8 | H63: IT-B | I63: 17-ITB36-21
C64: Capgemini* | E64: 59 | F64: SINGH NIKHIL SACHIDANAND MAMTA | G64: 6.8 | H64: IT-B | I64: 17-ITB38-21
C65: Capgemini | E65: 60 | F65: SINGH RITESH AMRESH MADHURI | G65: 3.8 | H65: IT-B | I65: 17-ITB39-21
C66: Capgemini | E66: 61 | F66: SOLANKI SWATI MAHENDRASINGH RAGINI ( Alredy plcaed in Infosys) | G66: 3.8 | H66: IT-B | I66: #N/A
C67: Capgemini* | E67: 62 | F67: THANKI RIDDHI ANIL NEELAM (Already placed in Oracle) | G67: 6.8 | H67: IT-B | I67: 17-ITB45-21
C68: Capgemini | E68: 63 | F68: UPADHYAY PRAKASH SANTOSH URMILA ( Alredy plcaed in Accenture) | G68: 3.8 | H68: IT-B | I68: #N/A
...
